Workbook

Sheet Cover
B2: MWG AFTER THE DMX IPO
B4: Three-statement history · IPO bridge · DMX FCFF DCF · MWG SOTP · scenario & QA model
B8: MODEL CONTROL & PUBLICATION STATUS
B9: Model version | C9: 2.0.0 | G9: Formula and workbook architecture version
B10: Data cut-off | C10: 46216 | G10: Official facts known at this date
B11: Generated at | C11: 46216.917 | G11: Local build timestamp
B12: Active scenario | C12: =Assumptions!$C$4 | G12: Bear / Base / Bull selector
B13: Display unit | C13: VND bn unless stated | G13: Share count in million; price in VND/share
B14: Valuation date | C14: N/A | G14: No same-date market price supplied
B15: Market conclusion | C15: UNAVAILABLE | G15: Guarded until price, price date and diluted shares are verified
B18: WHAT THIS MODEL ANSWERS
B19: 1. How did the actual IPO change DMX shares and primary capital raised?
B20: 2. What does an illustrative FCFF DCF imply for 100% of DMX under transparent drivers?
B21: 3. How much of DMX's value is attributable to MWG using an explicitly labelled ownership proxy?
B22: 4. What illustrative residual value is assigned to BHX and other MWG assets in a SOTP?
B23: 5. Which assumptions drive the range, and which QA gates prevent an unsupported conclusion?
B24: 6. Do earnings, working capital, cash and retained earnings reconcile across the three statements?
B26: WORKBOOK MAP
B27: Tab | C27: Purpose | G27: Primary status | I27: Reviewer focus
B28: Sources | C28: Official source registry and URLs | G28: Official metadata | I28: Provenance
B29: IPO_Bridge | C29: Planned versus actual primary issuance | G29: Actual + planned | I29: Shares/proceeds identity
B30: Q1_Actuals | C30: Key consolidated statements and ratios | G30: Actual | I30: Statement/cash checks
B31: 3Y_Statements | C31: FY2023–FY2025 plus Q1 2026 three-statement history | G31: Reported actuals | I31: Trend and scope
B32: 3S_Bridges | C32: NPAT-to-CFO, cash, retained earnings and normalization | G32: Actual + management LFL | I32: Accounting linkage
B33: WC_QoE | C33: Working-capital days and quality-of-earnings matrix | G33: Calculated | I33: Cash conversion risk
B34: Mgmt_Forecast | C34: 2025 actual and 2026–2030 company outlook | G34: Actual / company outlook | I34: No relabelling as analyst forecast
B35: Assumptions | C35: Editable Bear/Base/Bull inputs | G35: Illustrative | I35: Replace before investment use
B36: DMX_Valuation | C36: Driver-based FCFF DCF and equity bridge | G36: Illustrative forecast | I36: WACC, TV, double count
B37: MWG_SOTP | C37: Equity-level SOTP and holdco discount | G37: Illustrative | I37: Ownership and perimeter
B38: Scenarios | C38: Independent scenario calculations and sensitivities | G38: Illustrative | I38: Range, not target price
B39: Checks | C39: Critical QA and publication gates | G39: Control | I39: PASS/FAIL/WARN
B42: DISCLAIMER — Portfolio case study only. Not investment research, a recommendation, or an offer to buy/sell securities. Official facts remain subject to source documents. Management outlook is not a guarantee. All yellow/blue inputs are illustrative analyst assumptions. No market upside/downside is shown because same-date price inputs are absent.

Sheet Sources
A1: Source registry
A2: Official issuer documents used in the model; retrieved 13-Jul-2026
A4: Source ID | B4: Issuer | C4: Document type | D4: Title | E4: Period end | F4: Published | G4: Retrieved | H4: Audit status | I4: Scope | J4: Official URL | K4: Local artifact | L4: Model use | M4: Notes / limitations
A5: DMX-IPO-SALESKIT | B5: DMX | C5: Investor presentation / sales kit | D5: DMX IPO sales kit | E5: 46022 | G5: 46216 | H5: N/A | I5: Company presentation | J5: https://cdnv2-tmdt.tgdd.vn/mwgvn/investorrelations/files/posts/2026/5/5005818/d8/6b/d86b5d707c2c0b5baea9dbcffafaaa50.pdf | K5: data/raw/dmx/dmx_ipo_presentation_2026.pdf | L5: Planned IPO terms and management outlook | M5: Company-provided material; forecasts are not guarantees.
A6: DMX-IPO-RES14 | B6: DMX | C6: Board resolution / IPO result | D6: Resolution No. 14 on actual IPO result | F6: 46203 | G6: 46216 | H6: N/A | I6: Issuer disclosure | J6: https://cdnv2-tmdt.tgdd.vn/mwgvn/investorrelations/files/posts/2026/7/0/f1/08/f108ca2a7399d9a70674915a4b2cf651.pdf | K6: N/A (source linked; raw files are git-ignored) | L6: Actual allocated/cancelled/post-IPO shares and proceeds | M6: Primary source for the actual IPO bridge.
A7: DMX-IPO-COMPLETE | B7: DMX | C7: Issuer announcement | D7: DMX completes IPO and raises more than VND 13,315bn | F7: 46203 | G7: 46216 | H7: N/A | I7: Issuer announcement | J7: https://www.dmx.vn/eng/news/dien-may-xanh-completes-landmark-ipo-raising-more-than-vnd-13-315-billion-and-lifting-charter-capital-to-vnd-12-677-billion-5002485 | K7: N/A | L7: Rounded MWG ownership disclosure and transaction context | M7: 'Nearly 86%' is a reasonableness check, not exact ownership.
A8: DMX_IPO_PROCEEDS_2026 | B8: DMX | C8: Board resolution / use of proceeds | D8: Resolution No. 15 on adjusted use of IPO proceeds | F8: 46210 | G8: 46216 | H8: N/A | I8: Issuer disclosure | J8: https://cdnv2-tmdt.tgdd.vn/mwgvn/investorrelations/files/posts/2026/7/0/38/65/38651afbcd5d099f0e968015b88da8ee.pdf | K8: data/raw/dmx/dmx_ipo_proceeds_adjustment_2026.pdf | L8: Estimated issue costs, net proceeds and planned debt repayment | M8: Gross proceeds are actual; costs and net proceeds are issuer estimates. Debt repayment remains pro forma until actual disbursement is evidenced.
A9: DMX_FS_2024_C | B9: DMX | C9: Audited consolidated financial statements | D9: DMX consolidated financial statements FY2024 | E9: 45657 | F9: 46164 | G9: 46216 | H9: FY2024 audited; FY2023 comparative expressly unaudited | I9: Consolidated | J9: https://cdnv2-tmdt.tgdd.vn/mwgvn/investorrelations/files/posts/2026/5/0/93/e5/93e558113d3fa242567df336db5e4af6.pdf | K9: data/raw/dmx/dmx_fy2024_audited_consolidated.pdf | L9: FY2023 comparative and FY2024 historical statements | M9: Primary source for the three-statement history; FY2023 is not presented as audited.
A10: DMX_FS_2025_C | B10: DMX | C10: Audited consolidated financial statements | D10: DMX consolidated financial statements FY2025 | E10: 46022 | F10: 46164 | G10: 46216 | H10: Audited | I10: Consolidated | J10: https://cdnv2-tmdt.tgdd.vn/mwgvn/investorrelations/files/posts/2026/5/0/08/af/08af79013e9b9bdb210eb476e2fa7b95.pdf | K10: data/raw/dmx/dmx_fy2025_audited_consolidated.pdf | L10: FY2025 historical statements and FY2024 comparatives | M10: Primary audited source for FY2025 three-statement analysis.
A11: DMX_DATA_2026Q1 | B11: DMX | C11: Interim financial statements and data pack | D11: DMX Q1 2026 consolidated financial statements | E11: 46112 | G11: 46216 | H11: Unaudited | I11: Consolidated | J11: https://cdnv2-tmdt.tgdd.vn/mwgvn/investorrelations/files/posts/2026/6/0/6b/e5/6be50a510e272451464dae07771401ca.xlsx | K11: data/raw/dmx/dmx_q1_2026_data_pack.xlsx | L11: Q1 2026 actual balance sheet, income statement and cash flow | M11: Model values are in VND bn; source workbook is in VND.
A12: DMX_RESULTS_2026H1 | B12: DMX | C12: Business update | D12: DMX business results — six months 2026 | E12: 46203 | G12: 46216 | H12: Unaudited | I12: Company LFL operating update | J12: https://cdnv2-tmdt.tgdd.vn/mwgvn/investorrelations/files/posts/2026/7/5006021/b5/ee/b5ee17c283b469b12b3b435d00da8aa4.pdf | K12: N/A | L12: Operating KPI context only | M12: Not used as a substitute for audited/interim financial statements.
A13: DMX-OUTLOOK | B13: DMX | C13: Investor presentation | D13: DMX 2026–2030 management outlook | E13: 47848 | G13: 46216 | H13: N/A | I13: Company outlook | J13: https://cdnv2-tmdt.tgdd.vn/mwgvn/investorrelations/files/posts/2026/6/5005889/4a/f4/4af4a4152a74661a28063a23b4d6747f.pdf | K13: N/A | L13: Management revenue, NPAT and gross-margin outlook | M13: Separated from analyst forecast and actuals.
A14: MWG-AR-2025 | B14: MWG | C14: Annual report | D14: MWG Annual Report 2025 | E14: 46022 | G14: 46216 | H14: Audited sections as identified in report | I14: Consolidated / corporate | J14: https://cdnv2.tgdd.vn/mwgvn/investorrelations/files/posts/2026/3/5677/48/8a/488ab752e1224bcbd9dd5413be04179f.pdf | K14: data/raw/mwg/mwg_annual_report_2025.pdf | L14: Group context and perimeter | M14: No current MWG market price is imported into this workbook.
A15: MWG-ERABLUE-JV | B15: MWG | C15: Issuer article | D15: MWG describes EraBlue as a joint venture | G15: 46216 | H15: N/A | I15: Issuer article | J15: https://mwg.vn/tin-tuc/erablue-buoc-chuyen-minh-cua-the-gioi-di-dong-o-quoc-gia-dong-dan-nhat-asean-179 | K15: N/A | L15: Perimeter and double-counting control | M15: EraBlue is included once inside DMX in this illustrative model.
A18: Repository policy: raw issuer documents are git-ignored. The build script embeds only the derived official facts needed for reproducibility and links each fact to the issuer source. If the local Q1 data pack is present, the build verifies representative embedded values against it before saving the model.

Sheet IPO_Bridge
A1: DMX IPO bridge — planned vs actual close
A2: Primary issuance; MWG did not receive the gross proceeds. Shares in million, values in VND bn unless stated.
A4: Metric | B4: Unit | C4: Planned | D4: Actual close | E4: Status | F4: Source / formula | G4: Interpretation | H4: Control
A5: IPO offer price | B5: VND/share | C5: 80000 | D5: 80000 | E5: Actual / planned | F5: DMX-IPO-SALESKIT; DMX-IPO-RES14 | G5: Primary offer price | H5: =IF(C5=D5,"PASS","FAIL")
A6: Shares before IPO | B6: mn shares | C6: 1101.2835 | D6: 1101.2835 | E6: Actual | F6: DMX-IPO-RES14 | G6: Opening share count
A7: Shares offered | B7: mn shares | C7: 179.5004 | D7: 179.5004 | E7: Actual / planned | F7: DMX-IPO-SALESKIT; DMX-IPO-RES14 | G7: Maximum primary shares offered
A8: Shares registered | B8: mn shares | C8: N/A | D8: 166.4858 | E8: Actual | F8: DMX-IPO-RES14 | G8: Registered, not necessarily allocated
A9: Shares successfully allocated | B9: mn shares | C9: 179.5004 | D9: 166.4385 | E9: Actual / planned | F9: DMX-IPO-RES14 | G9: Actual case uses only paid/allocated shares
A10: Shares cancelled | B10: mn shares | C10: =C7-C9 | D10: 13.0619 | E10: Actual | F10: DMX-IPO-RES14 | G10: Unallocated shares were cancelled | H10: =IF(ABS(D7-D9-D10)<0.000001,"PASS","FAIL")
A11: Shares after IPO | B11: mn shares | C11: =C6+C9 | D11: 1267.722 | E11: Actual | F11: DMX-IPO-RES14 | G11: Post-IPO diluted share count | H11: =IF(ABS((D6+D9)-D11)<0.000001,"PASS","FAIL")
A12: Gross proceeds | B12: VND bn | C12: =C9*C5/1000 | D12: =D9*D5/1000 | E12: Calculated from actual | F12: Shares allocated × offer price | G12: Cash raised by DMX before issue costs | H12: =IF(ABS(D9*D5/1000-13315.080)<0.001,"PASS","FAIL")
A13: Subscription rate | B13: % | C13: =C9/C7 | D13: =D9/D7 | E13: Calculated | F13: Allocated / offered | G13: Actual take-up of the offer
A14: New shares / post-money shares | B14: % | C14: =C9/C11 | D14: =D9/D11 | E14: Calculated | F14: New / post shares | G14: Primary dilution percentage
A15: Pre-money equity value at IPO price | B15: VND bn | C15: =C6*C5/1000 | D15: =D6*D5/1000 | E15: Calculated | F15: Pre shares × offer price | G15: Transaction-price identity, not independent fair value
A16: Post-money equity value at IPO price | B16: VND bn | C16: =C11*C5/1000 | D16: =D11*D5/1000 | E16: Calculated | F16: Post shares × offer price | G16: Transaction-price identity, not a market conclusion | H16: =IF(ABS(D15+D12-D16)<0.001,"PASS","FAIL")
A17: MWG ownership after IPO | B17: % | C17: N/A | D17: 0.86 | E17: Approximate disclosure | F17: DMX-IPO-COMPLETE | G17: 'Nearly 86%' only; exact shares remain unverified | H17: =IF(ABS(D17-86%)<=1%,"PASS — rounded","WARN")
A18: Estimated issue costs | B18: VND bn | C18: N/A | D18: 100 | E18: Issuer estimate | F18: DMX_IPO_PROCEEDS_2026 | G18: Estimated transaction costs; not a final reported cash outflow | H18: =IF(ABS(D18-100)<0.001,"PASS","FAIL")
A19: Estimated net proceeds | B19: VND bn | C19: N/A | D19: =D12-D18 | E19: Issuer estimate | F19: DMX_IPO_PROCEEDS_2026 | G19: Gross proceeds less estimated issue costs | H19: =IF(ABS(D19-13215.080)<0.001,"PASS","FAIL")
A20: Net IPO proceeds adjustment in DCF bridge | B20: VND bn | C20: N/A | D20: =D19 | E20: Pro forma | F20: Resolution 15 after 31-Mar-2026 balance date | G20: Included once because the DCF uses pre-IPO Q1 cash/debt with post-IPO shares | H20: =IF(ABS(D20-D19)<0.001,"PASS","FAIL")
A23: Accounting boundary: this is a primary issuance. Gross proceeds belong to DMX, not MWG. The DCF bridges 31-Mar-2026 pre-IPO cash/debt to a post-IPO share count, so estimated net proceeds of VND 13,215.08bn are added exactly once. Resolution 15 earmarks the proceeds for debt repayment, but this is labelled pro forma until actual disbursement is evidenced. Exact MWG ownership is not inferred from the rounded 'nearly 86%' announcement.

Sheet Q1_Actuals
A1: DMX Q1 2026 actuals | N1: ← Cover
A2: Consolidated issuer data pack; reported signs preserved. P&L/CF compare Q1; BS compares 31-Mar-2026 with 31-Dec-2025. | L2: Metric | M2: Q1 2026 | N2: Q1 2025
L3: Revenue | M3: =D6 | N3: =E6
A4: Statement | B4: Line item | C4: Unit | D4: Current period | E4: Comparator | F4: Change / ratio | G4: Source ID | H4: Source locator | I4: Status | J4: Notes | L4: Gross profit | M4: =D8 | N4: =E8
A5: INCOME STATEMENT — Q1 2026 vs Q1 2025 | VND bn except EPS and ratios | L5: NPAT | M5: =D20 | N5: =E20
A6: IS | B6: Net revenue | C6: VND bn | D6: 32541.95 | E6: 25153.558 | F6: =ABS(D6)/ABS(E6)-1 | G6: DMX_DATA_2026Q1 | H6: Income Statement — Net revenue | I6: Actual
A7: IS | B7: Cost of goods sold | C7: VND bn | D7: -26300.729 | E7: -20627.387 | F7: =ABS(D7)/ABS(E7)-1 | G7: DMX_DATA_2026Q1 | H7: Income Statement — Cost of goods sold | I7: Actual | J7: Reported as a negative expense
A8: IS | B8: Gross profit | C8: VND bn | D8: 6241.2213 | E8: 4526.1716 | F8: =D8/E8-1 | G8: DMX_DATA_2026Q1 | H8: Income Statement — Gross profit | I8: Actual
A9: IS | B9: Gross margin | C9: % | D9: =D8/D6 | E9: =E8/E6 | F9: =D9-E9 | G9: MODEL-FORMULA | H9: Gross profit / net revenue | I9: Calculated | J9: Change shown in percentage points
A10: IS | B10: Financial income | C10: VND bn | D10: 512.11716 | E10: 436.15197 | F10: =D10/E10-1 | G10: DMX_DATA_2026Q1 | H10: Income Statement — Financial income | I10: Actual
A11: IS | B11: Financial expense | C11: VND bn | D11: -326.14182 | E11: -202.42328 | F11: =ABS(D11)/ABS(E11)-1 | G11: DMX_DATA_2026Q1 | H11: Income Statement — Financial expense | I11: Actual | J11: Reported as a negative expense
A12: IS | B12: Interest expense | C12: VND bn | D12: -324.56987 | E12: -201.6418 | F12: =ABS(D12)/ABS(E12)-1 | G12: DMX_DATA_2026Q1 | H12: Income Statement — Interest expense | I12: Actual
A13: IS | B13: Selling expense | C13: VND bn | D13: -2438.3745 | E13: -2139.5798 | F13: =ABS(D13)/ABS(E13)-1 | G13: DMX_DATA_2026Q1 | H13: Income Statement — Selling expense | I13: Actual
A14: IS | B14: G&A expense | C14: VND bn | D14: -1225.141 | E14: -771.42346 | F14: =ABS(D14)/ABS(E14)-1 | G14: DMX_DATA_2026Q1 | H14: Income Statement — G&A expense | I14: Actual
A15: IS | B15: Share of profit from JV | C15: VND bn | D15: 9.0117419 | E15: 3.1297743 | F15: =D15/E15-1 | G15: DMX_DATA_2026Q1 | H15: Income Statement — Share of JV profit | I15: Actual | J15: EraBlue is treated as a JV perimeter control
A16: IS | B16: Operating profit | C16: VND bn | D16: 2772.6929 | E16: 1852.0268 | F16: =D16/E16-1 | G16: DMX_DATA_2026Q1 | H16: Income Statement — Operating profit | I16: Actual
A17: IS | B17: Operating margin | C17: % | D17: =D16/D6 | E17: =E16/E6 | F17: =D17-E17 | G17: MODEL-FORMULA | H17: Operating profit / revenue | I17: Calculated | J17: Company line includes finance and JV effects; not used as DCF EBIT
A18: IS | B18: Profit before tax | C18: VND bn | D18: 2775.4415 | E18: 1856.5649 | F18: =D18/E18-1 | G18: DMX_DATA_2026Q1 | H18: Income Statement — Profit before tax | I18: Actual
A19: IS | B19: Income tax expense | C19: VND bn | D19: -556.87459 | E19: -378.1895 | F19: =ABS(D19)/ABS(E19)-1 | G19: DMX_DATA_2026Q1 | H19: Income Statement — current + deferred tax | I19: Actual
A20: IS | B20: Net profit after tax | C20: VND bn | D20: 2218.5669 | E20: 1478.3754 | F20: =D20/E20-1 | G20: DMX_DATA_2026Q1 | H20: Income Statement — NPAT | I20: Actual
A21: IS | B21: NPAT margin | C21: % | D21: =D20/D6 | E21: =E20/E6 | F21: =D21-E21 | G21: MODEL-FORMULA | H21: NPAT / revenue | I21: Calculated | J21: Change shown in percentage points
A22: IS | B22: Basic EPS | C22: VND/share | D22: 2015 | E22: 1342 | F22: =D22/E22-1 | G22: DMX_DATA_2026Q1 | H22: Income Statement — Basic EPS | I22: Actual
A24: BALANCE SHEET — 31-Mar-2026 vs 31-Dec-2025 | VND bn
A25: BS | B25: Cash & cash equivalents | C25: VND bn | D25: 3312.6786 | E25: 3578.1549 | F25: =IFERROR(D25/E25-1,"N/A") | G25: DMX_DATA_2026Q1 | H25: Balance Sheet — Cash & cash equivalents | I25: Actual
A26: BS | B26: Short-term held-to-maturity investments | C26: VND bn | D26: 25255.709 | E26: 25246.515 | F26: =IFERROR(D26/E26-1,"N/A") | G26: DMX_DATA_2026Q1 | H26: Balance Sheet — Short-term investments | I26: Actual
A27: BS | B27: Long-term held-to-maturity investments | C27: VND bn | D27: 1499.5024 | E27: 1400 | F27: =IFERROR(D27/E27-1,"N/A") | G27: DMX_DATA_2026Q1 | H27: Balance Sheet — Long-term held-to-maturity investments | I27: Actual
A28: BS | B28: Cash + term deposits | C28: VND bn | D28: =D25+D26+D27 | E28: =E25+E26+E27 | F28: =IFERROR(D28/E28-1,"N/A") | G28: MODEL-FORMULA | H28: Cash + short-term investments + long-term deposits | I28: Calculated
A29: BS | B29: Current receivables | C29: VND bn | D29: 1612.0508 | E29: 1432.5649 | F29: =IFERROR(D29/E29-1,"N/A") | G29: DMX_DATA_2026Q1 | H29: Balance Sheet — Current receivables | I29: Actual
A30: BS | B30: Inventory, net | C30: VND bn | D30: 23054.447 | E30: 22759.102 | F30: =IFERROR(D30/E30-1,"N/A") | G30: DMX_DATA_2026Q1 | H30: Balance Sheet — Inventories | I30: Actual
A31: BS | B31: Inventory provision | C31: VND bn | D31: -749.03236 | E31: -609.59416 | F31: =IFERROR(D31/E31-1,"N/A") | G31: DMX_DATA_2026Q1 | H31: Balance Sheet — Inventory provision | I31: Actual
A32: BS | B32: Fixed assets, net | C32: VND bn | D32: 751.59697 | E32: 840.47279 | F32: =IFERROR(D32/E32-1,"N/A") | G32: DMX_DATA_2026Q1 | H32: Balance Sheet — Fixed assets | I32: Actual
A33: BS | B33: Investment in jointly controlled entity | C33: VND bn | D33: 502.56116 | E33: 371.15906 | F33: =IFERROR(D33/E33-1,"N/A") | G33: DMX_DATA_2026Q1 | H33: Balance Sheet — JV investment | I33: Actual
A34: BS | B34: Total assets | C34: VND bn | D34: 57327.01 | E34: 56916.238 | F34: =IFERROR(D34/E34-1,"N/A") | G34: DMX_DATA_2026Q1 | H34: Balance Sheet — Total assets | I34: Actual
A35: BS | B35: Short-term trade payables | C35: VND bn | D35: 8598.5467 | E35: 9701.5945 | F35: =IFERROR(D35/E35-1,"N/A") | G35: DMX_DATA_2026Q1 | H35: Balance Sheet — Trade payables | I35: Actual
A36: BS | B36: Short-term debt | C36: VND bn | D36: 22158.891 | E36: 23429.114 | F36: =IFERROR(D36/E36-1,"N/A") | G36: DMX_DATA_2026Q1 | H36: Balance Sheet — Short-term loans | I36: Actual
A37: BS | B37: Total liabilities | C37: VND bn | D37: 37307.872 | E37: 39115.666 | F37: =IFERROR(D37/E37-1,"N/A") | G37: DMX_DATA_2026Q1 | H37: Balance Sheet — Total liabilities | I37: Actual
A38: BS | B38: Total equity | C38: VND bn | D38: 20019.138 | E38: 17800.572 | F38: =IFERROR(D38/E38-1,"N/A") | G38: DMX_DATA_2026Q1 | H38: Balance Sheet — Equity | I38: Actual
A39: BS | B39: Cash + deposits − debt | C39: VND bn | D39: =D28-D36 | E39: =E28-E36 | F39: =IFERROR(D39/E39-1,"N/A") | G39: MODEL-FORMULA | H39: Calculated liquidity bridge | I39: Calculated
A41: CASH FLOW STATEMENT — Q1 2026 vs Q1 2025 | VND bn
A42: CF | B42: Net cash from operating activities | C42: VND bn | D42: 863.68677 | E42: 2477.0492 | F42: =IFERROR(D42/E42-1,"N/A") | G42: DMX_DATA_2026Q1 | H42: Cash Flow — CFO | I42: Actual
...

Sheet 3Y_Statements
A1: DMX three-statement history
A2: FY2023 comparative, FY2024–FY2025 statutory actuals and Q1 2026 latest actual; VND bn unless stated.
B5: Line item | C5: FY2023A | D5: FY2024A | E5: FY2025A | F5: Q1 2026A | H5: Coverage control: FY2023 is the comparative column in the FY2024 filing and is expressly unaudited. FY2024 and FY2025 are audited consolidated statutory actuals. Q1 2026 is unaudited. The H1 2026 issuer update is not presented as a financial statement.
B6: Audit status | C6: comparative unaudited | D6: audited | E6: audited | F6: unaudited
B7: Scope / basis | C7: DMX consolidated · reported | D7: DMX consolidated · reported | E7: DMX consolidated · reported | F7: DMX consolidated · reported
B9: INCOME STATEMENT
B10: Net revenue | C10: 86822.143 | D10: 93356.608 | E10: 109479.19 | F10: 32541.95
B11: Cost of goods sold | C11: -72403.597 | D11: -76267.2 | E11: -89992.478 | F11: -26300.729
B12: Gross profit | C12: 14418.546 | D12: 17089.408 | E12: 19486.711 | F12: 6241.2213
B13: Gross margin | C13: =C12/C10 | D13: =D12/D10 | E13: =E12/E10 | F13: =F12/F10
B14: Financial income | C14: 1707.1667 | D14: 1673.1776 | E14: 1842.8897 | F14: 512.11716
B15: Financial expense | C15: -1082.0116 | D15: -700.52581 | E15: -973.3776 | F15: -326.14182
B16: Reported operating profit | C16: 2004.0373 | D16: 5084.037 | E16: 7240.3958 | F16: 2772.6929
B17: Operating margin | C17: =C16/C10 | D17: =D16/D10 | E17: =E16/E10 | F17: =F16/F10
B18: Profit before tax | C18: 1799.2869 | D18: 4746.5144 | E18: 7268.6987 | F18: 2775.4415
B19: Income-tax expense | C19: -453.78569 | D19: -1029.9435 | E19: -1466.9135 | F19: -556.87459
B20: Net profit after tax | C20: 1345.5012 | D20: 3716.571 | E20: 5801.7852 | F20: 2218.5669
B21: Net margin | C21: =C20/C10 | D21: =D20/D10 | E21: =E20/E10 | F21: =F20/F10
B23: BALANCE SHEET
B24: Cash and cash equivalents | C24: 4139.9297 | D24: 3780.1283 | E24: 3578.1549 | F24: 3312.6786
B25: Short-term investments | C25: 15742.181 | D25: 19463.431 | E25: 20414.245 | F25: 25255.709 | H25: Formula evidence
B26: Trade receivables | C26: 298.85768 | D26: 241.76886 | E26: 394.56441 | F26: 293.38613 | H26: Gross profit = revenue + signed COGS
B27: Gross inventory | C27: 18442.493 | D27: 18868.714 | E27: 23368.696 | F27: 23803.479 | H27: Closing cash = opening cash + CFO + CFI + CFF + FX
B28: Inventory provision | C28: -204.4489 | D28: -423.09769 | E28: -609.59416 | F28: -749.03236 | H28: Balance check = assets − liabilities − equity
B29: Net inventory | C29: 18238.044 | D29: 18445.616 | E29: 22759.102 | F29: 23054.447 | H29: CFO/NPAT is read with seasonality and working-capital drivers
B30: Trade payables | C30: 5457.0402 | D30: 6325.1099 | E30: 9701.5945 | F30: 8598.5467
B31: Total borrowings | C31: 20306.116 | D31: 19930.173 | E31: 23429.114 | F31: 22158.891
B32: Retained earnings | C32: 14188.327 | D32: 15154.898 | E32: 5714.4054 | F32: 7932.9723
B33: Total assets | C33: 46427.545 | D33: 49472.143 | E33: 56916.238 | F33: 57327.01
B34: Total liabilities | C34: 27873.959 | D34: 29955.726 | E34: 39115.666 | F34: 37307.872
B35: Total equity | C35: 18553.585 | D35: 19516.417 | E35: 17800.572 | F35: 20019.138
B36: Assets − liabilities − equity | C36: =IF(OR(NOT(ISNUMBER(C33)),NOT(ISNUMBER(C34)),NOT(ISNUMBER(C35))),"N/D",C33-C34-C35) | D36: =IF(OR(NOT(ISNUMBER(D33)),NOT(ISNUMBER(D34)),NOT(ISNUMBER(D35))),"N/D",D33-D34-D35) | E36: =IF(OR(NOT(ISNUMBER(E33)),NOT(ISNUMBER(E34)),NOT(ISNUMBER(E35))),"N/D",E33-E34-E35) | F36: =IF(OR(NOT(ISNUMBER(F33)),NOT(ISNUMBER(F34)),NOT(ISNUMBER(F35))),"N/D",F33-F34-F35)
B38: CASH-FLOW STATEMENT
B39: Depreciation and amortization | C39: 1449.2079 | D39: 1086.3165 | E39: 775.21019 | F39: 137.82967
B40: Cash flow from operations | C40: 2357.297 | D40: 6243.0784 | E40: 5016.7314 | F40: 863.68677
B41: Cash flow from investing | C41: -8805.1039 | D41: -3477.0402 | E41: 12.070378 | F41: 140.14649
B42: Cash flow from financing | C42: 7212.4835 | D42: -3125.9438 | E42: -5230.8322 | F42: -1270.2235
B43: Opening cash | C43: N/D | D43: N/D | E43: N/D | F43: N/D
B44: FX effect | C44: N/D | D44: N/D | E44: N/D | F44: N/D
B45: Closing cash | C45: N/D | D45: N/D | E45: N/D | F45: N/D
...

Sheet 3S_Bridges
A1: Three-statement reconciliation bridges
A2: Q1 2026 earnings-to-cash, cash roll-forward, FY2025 retained earnings, normalization and IPO pro forma controls.
A4: NPAT → CFO · Q1 2026 | F4: Opening cash → closing cash · Q1 2026 | K4: Retained earnings · FY2025
A5: Net profit after tax | B5: 2218.5669 | F5: Opening cash | G5: 3578.1549 | K5: Opening retained earnings | L5: 15154.898
A6: Add: P&L income-tax expense | B6: 556.87459 | F6: Cash flow from operations | G6: 863.68677 | K6: NPAT attributable to parent | L6: 5801.7852
A7: Depreciation and amortization | B7: 137.82967 | F7: Cash flow from investing | G7: 140.14649 | K7: Dividends paid | L7: -8700
A8: Provisions / reversals | B8: 148.32157 | F8: Cash flow from financing | G8: -1270.2235 | K8: Capitalisation / other equity movements | L8: -6542.2782
A9: Non-cash FX revaluation | B9: -0.91392713 | F9: FX effect | G9: 0.91392713 | K9: Calculated total | L9: =SUM(L5:L8)
A10: Remove investing profit | B10: -478.81474 | F10: Calculated total | G10: =SUM(G5:G9) | K10: Reported total | L10: 5714.4054
A11: Add back interest expense | B11: 324.56987 | F11: Reported total | G11: 3312.6786 | K11: Difference | L11: =L10-L9
A12: Change in receivables | B12: -79.604724 | F12: Difference | G12: =G11-G10 | K12: Control | L12: =IF(ABS(L11)<0.001,"PASS","FAIL")
A13: Change in inventory | B13: -434.78312 | F13: Control | G13: =IF(ABS(G12)<0.001,"PASS","FAIL") | K13: FY2025 residual captures the disclosed capital restructuring and other equity movements; it is not treated as an operating adjustment.
A14: Change in payables | B14: -465.97675 | F14: All components preserve the reported cash-flow sign convention.
A15: Change in prepayments | B15: 33.250162
A16: Interest paid | B16: -315.36802
A17: Corporate income tax paid | B17: -780.26469
A18: Calculated total | B18: =SUM(B5:B17)
A19: Reported total | B19: 863.68677
A20: Difference | B20: =B19-B18
A21: Control | B21: =IF(ABS(B20)<0.001,"PASS","FAIL")
A22: All components preserve the reported cash-flow sign convention.
A27: FY2025 REPORTED → MANAGEMENT LFL NORMALIZATION
A28: Reported item | B28: Reported | C28: Adjustment | D28: LFL comparator | E28: Treatment | F28: Reason
A29: Net revenue | B29: 109479.19 | C29: -2479.1885 | D29: 107000 | E29: management_lfl_comparator | F29: Management's FY2025 LFL perimeter excludes An Khang and AvaKids and includes Thợ Điện Máy Xanh; this comparator does not overwrite the statutory actual. | I29: DMX_FS_2025_C|DMX_IPO_PRESENTATION_2026
A30: NPAT attributable to parent | B30: 5801.7852 | C30: 273.21477 | D30: 6075 | E30: management_lfl_comparator | F30: Only the disclosed management-adjusted headline is bridged; no unsupported allocation is made to EBIT, working capital or cash flow. | I30: DMX_FS_2025_C|DMX_IPO_PRESENTATION_2026
A31: Operating profit | B31: 7240.3958 | C31: N/D | D31: N/D | E31: not_adjusted | F31: No sufficiently granular disclosure exists to normalize the statutory operating-profit line across the perimeter change. | I31: DMX_FS_2025_C
A32: Cash and cash equivalents | B32: 3578.1549 | C32: N/D | D32: N/D | E32: not_adjusted | F32: Minimum operating cash is not disclosed; cash-like balances are not automatically classified as excess cash. | I32: DMX_FS_2025_C
A33: Total debt | B33: 23429.114 | C33: N/D | D33: N/D | E33: not_adjusted | F33: Lease and debt conventions are not sufficiently disclosed for a supported adjusted-net-debt figure. | I33: DMX_FS_2025_C
A36: POST-IPO PRO FORMA — TRANSACTION, NOT REPORTED H1 ACTUAL
A38: Gross primary proceeds | B38: 13315.08 | C38: Official actual
A39: Estimated issue costs | B39: -100 | C39: Resolution 15; estimate at 6-Jul-2026
A40: Estimated net proceeds | B40: =B38+B39 | C40: VND 13,215.08bn
A41: Debt repayment plan | B41: =-B40 | C41: Earmarked for 2026; not evidence of completed repayment
A42: Pro forma liquidity retained | B42: =SUM(B40:B41) | C42: Zero under disclosed use-of-proceeds plan

Sheet WC_QoE
A1: Working capital and quality of earnings
A2: Trade-balance days use average opening/closing balances and actual elapsed days; Q1 remains seasonality-sensitive.
B4: Metric | C4: FY2024A | D4: FY2025A | E4: Q1 2026A | G4: Senior interpretation: CCC improved from roughly 61 days in FY2024 to 52 days in FY2025. Q1 2026 screens near 48 days on a 90-day YTD denominator, but this is not directly equivalent to a full-year seasonal outcome.
B5: Actual period days | C5: 366 | D5: 365 | E5: 90
B6: Average net inventory | C6: =('3Y_Statements'!C29+'3Y_Statements'!D29)/2 | D6: =('3Y_Statements'!D29+'3Y_Statements'!E29)/2 | E6: =('3Y_Statements'!E29+'3Y_Statements'!F29)/2
B7: Average trade receivables | C7: =('3Y_Statements'!C26+'3Y_Statements'!D26)/2 | D7: =('3Y_Statements'!D26+'3Y_Statements'!E26)/2 | E7: =('3Y_Statements'!E26+'3Y_Statements'!F26)/2
B8: Average trade payables | C8: =('3Y_Statements'!C30+'3Y_Statements'!D30)/2 | D8: =('3Y_Statements'!D30+'3Y_Statements'!E30)/2 | E8: =('3Y_Statements'!E30+'3Y_Statements'!F30)/2
B10: Days inventory outstanding | C10: =C6/ABS('3Y_Statements'!D11)*C5 | D10: =D6/ABS('3Y_Statements'!E11)*D5 | E10: =E6/ABS('3Y_Statements'!F11)*E5
B11: Days sales outstanding | C11: =C7/'3Y_Statements'!D10*C5 | D11: =D7/'3Y_Statements'!E10*D5 | E11: =E7/'3Y_Statements'!F10*E5
B12: Days payables outstanding | C12: =C8/ABS('3Y_Statements'!D11)*C5 | D12: =D8/ABS('3Y_Statements'!E11)*D5 | E12: =E8/ABS('3Y_Statements'!F11)*E5
B13: Cash conversion cycle | C13: =C10+C11-C12 | D13: =D10+D11-D12 | E13: =E10+E11-E12
B15: CFO / NPAT | C15: ='3Y_Statements'!D40/'3Y_Statements'!D20 | D15: ='3Y_Statements'!E40/'3Y_Statements'!E20 | E15: ='3Y_Statements'!F40/'3Y_Statements'!F20
B16: Cash CapEx / revenue | C16: =ABS('3Y_Statements'!D46)/'3Y_Statements'!D10 | D16: =ABS('3Y_Statements'!E46)/'3Y_Statements'!E10 | E16: =ABS('3Y_Statements'!F46)/'3Y_Statements'!F10
B17: Inventory provision / gross inventory | C17: =ABS('3Y_Statements'!D28)/'3Y_Statements'!D27 | D17: =ABS('3Y_Statements'!E28)/'3Y_Statements'!E27 | E17: =ABS('3Y_Statements'!F28)/'3Y_Statements'!F27
B18: CFO less CapEx | C18: ='3Y_Statements'!D47 | D18: ='3Y_Statements'!E47 | E18: ='3Y_Statements'!F47
B21: QUALITY OF EARNINGS — EVIDENCE, READ-THROUGH, OPEN RISK
B22: Indicator | C22: Observation | F22: Senior read-through | H22: What remains at risk | K22: Metric
B23: Revenue growth | C23: Q1 2026 revenue grew strongly year on year. | F23: Operating momentum is broad enough to warrant a full-year follow-through test. | H23: A single quarter does not establish sustainability or remove seasonality. | K23: 0.29373149
B24: Gross-margin change | C24: Gross margin expanded by approximately 119 bps year on year. | F24: Mix, pricing and operating leverage appear more supportive than pure volume growth. | H24: Category mix, promotions and vendor support may normalize. | K24: 0.011848419
B25: CFO / NPAT | C25: Quarterly cash conversion fell to about 39% from about 168%. | F25: The main swing is working capital, especially supplier funding, plus tax payments. | H25: Do not infer earnings manipulation without seasonal and H1 statement evidence. | K25: 0.38929941
B26: Payables contribution to CFO | C26: Payables absorbed cash in Q1 2026 after providing material funding in Q1 2025. | F26: Supplier financing explains more of the CFO gap than receivables or inventory alone. | H26: A sustained decline in supplier funding would pressure liquidity. | K26: -465.97675
B27: Inventory provision coverage | C27: Provision coverage rose from the FY2025 year-end level. | F27: The balance sheet recognizes more inventory risk as stock expands. | H27: Ageing, markdowns and category-level obsolescence remain undisclosed. | K27: 0.031467348
B28: Net finance contribution / PBT | C28: Net finance income contributes to reported profit but is not the primary growth driver. | F28: Core and treasury earnings should remain separately visible. | H28: Deposit income may change after IPO proceeds are used to repay debt. | K28: 0.067007481
B30: SENIOR CONTROL POINTS
B31: • IPO proceeds are primary capital of DMX, not cash received by MWG.
B32: • Resolution 15 discloses VND 13,215.08bn estimated net proceeds earmarked for debt repayment; this remains pro forma until disbursement is evidenced.
B33: • Cash plus deposits less debt is a liquidity indicator, not automatically distributable excess cash.
B34: • Financed-sales mix does not prove DMX bears customer credit risk; lender and risk-transfer terms must be verified.
B35: • EraBlue is equity-accounted and must be included once under a method-consistent valuation treatment.
B36: • Management LFL FY2025 is a comparator, not a replacement for statutory reported statements.

Sheet Mgmt_Forecast
A1: DMX management outlook
A2: 2025 actual shown in company material; 2026F–2030F are management outlook, not analyst estimates and not guarantees.
B4: Metric | C4: 2025A | D4: 2026F | E4: 2027F | F4: 2028F | G4: 2029F | H4: 2030F | I4: Source / status | J4: Interpretation
B5: Data status | C5: Actual (company presentation) | D5: Company outlook | E5: Company outlook | F5: Company outlook | G5: Company outlook | H5: Company outlook | I5: DMX-OUTLOOK | J5: Company outlook is held separate from the analyst scenario layer.
B6: Revenue | C6: 107000 | D6: 122500 | E6: 135000 | F6: 149000 | G6: 164000 | H6: 182000 | I6: DMX-OUTLOOK | J6: Company outlook is held separate from the analyst scenario layer.
B7: Revenue growth | C7: N/A | D7: =D6/C6-1 | E7: =E6/D6-1 | F7: =F6/E6-1 | G7: =G6/F6-1 | H7: =H6/G6-1 | I7: DMX-OUTLOOK | J7: Company outlook is held separate from the analyst scenario layer.
B8: NPAT | C8: 6075 | D8: 7350 | E8: 8500 | F8: 9800 | G8: 11300 | H8: 13000 | I8: DMX-OUTLOOK | J8: Company outlook is held separate from the analyst scenario layer.
B9: NPAT growth | C9: N/A | D9: =D8/C8-1 | E9: =E8/D8-1 | F9: =F8/E8-1 | G9: =G8/F8-1 | H9: =H8/G8-1 | I9: DMX-OUTLOOK | J9: Company outlook is held separate from the analyst scenario layer.
B10: NPAT margin | C10: =C8/C6 | D10: =D8/D6 | E10: =E8/E6 | F10: =F8/F6 | G10: =G8/G6 | H10: =H8/H6 | I10: DMX-OUTLOOK | J10: Company outlook is held separate from the analyst scenario layer.
B11: Gross margin | C11: 0.171 | D11: 0.175 | E11: 0.178 | F11: 0.18 | G11: 0.183 | H11: 0.184 | I11: DMX-OUTLOOK | J11: Company outlook is held separate from the analyst scenario layer.
B14: MODEL BOUNDARY — These values reproduce the company's published outlook as captured at the data cut-off. The DCF does not silently treat them as audited actuals: it applies a separate scenario growth adjustment and explicit EBIT, tax, D&A, capex and working-capital assumptions on the Assumptions tab.

Sheet Assumptions
A1: Illustrative analyst assumptions
A2: Yellow cells / blue font are editable inputs. None of the scenario values below is an official company forecast unless separately sourced.
A4: Active scenario | C4: Base
A5: Valuation date | C5: N/A | J5: Required for a market conclusion
A6: MWG closing price | C6: N/A | J6: VND/share; must have the same valuation date
A7: DMX market price | C7: N/A | J7: N/A before verified trading price/date
A8: Exact MWG ownership of DMX | C8: N/A | J8: Rounded 'nearly 86%' is not exact ownership
A10: Assumption ID | B10: Category | C10: Driver | D10: Unit | E10: Bear | F10: Base | G10: Bull | H10: Active | I10: Status | J10: Rationale | K10: Evidence / source
A11: OP_REV_GROWTH_ADJ | B11: DMX operations | C11: Annual adjustment to management revenue growth | D11: % | E11: -0.03 | F11: 0 | G11: 0.02 | H11: =INDEX(E11:G11,1,MATCH($C$4,$E$10:$G$10,0)) | I11: Illustrative | J11: Applied to the growth rate, not directly to revenue output | K11: Analyst scenario
A12: OP_EBIT_MARGIN_2026 | B12: DMX operations | C12: EBIT margin in 2026E | D12: % | E12: 0.07 | F12: 0.08 | G12: 0.088 | H12: =INDEX(E12:G12,1,MATCH($C$4,$E$10:$G$10,0)) | I12: Illustrative | J12: FCFF EBIT is independent from company NPAT outlook | K12: Analyst scenario
A13: OP_EBIT_MARGIN_STEP | B13: DMX operations | C13: Annual EBIT margin step | D13: % | E13: 0.001 | F13: 0.002 | G13: 0.0025 | H13: =INDEX(E13:G13,1,MATCH($C$4,$E$10:$G$10,0)) | I13: Illustrative | J13: Linear step from the 2026E margin | K13: Analyst scenario
A14: OP_CASH_TAX | B14: DMX operations | C14: Cash tax rate | D14: % | E14: 0.2 | F14: 0.2 | G14: 0.2 | H14: =INDEX(E14:G14,1,MATCH($C$4,$E$10:$G$10,0)) | I14: Illustrative | J14: Vietnam corporate-tax simplification; replace with modelled cash tax | K14: Analyst scenario
A15: OP_DA_PCT_REV | B15: DMX operations | C15: D&A as % of revenue | D15: % | E15: 0.01 | F15: 0.01 | G15: 0.01 | H15: =INDEX(E15:G15,1,MATCH($C$4,$E$10:$G$10,0)) | I15: Illustrative | J15: Required to bridge EBIT to FCFF | K15: Analyst scenario
A16: OP_CAPEX_PCT_REV | B16: DMX operations | C16: Capex as % of revenue | D16: % | E16: 0.012 | F16: 0.01 | G16: 0.009 | H16: =INDEX(E16:G16,1,MATCH($C$4,$E$10:$G$10,0)) | I16: Illustrative | J16: Maintenance and growth capex combined | K16: Analyst scenario
A17: OP_NWC_PCT_DELTA_REV | B17: DMX operations | C17: Cash investment in NWC as % of revenue increase | D17: % | E17: 0.04 | F17: 0.03 | G17: 0.02 | H17: =INDEX(E17:G17,1,MATCH($C$4,$E$10:$G$10,0)) | I17: Illustrative | J17: Positive value is a cash outflow | K17: Analyst scenario
A18: VAL_WACC | B18: DMX valuation | C18: Nominal VND WACC | D18: % | E18: 0.13 | F18: 0.12 | G18: 0.11 | H18: =INDEX(E18:G18,1,MATCH($C$4,$E$10:$G$10,0)) | I18: Illustrative | J18: Market inputs are not populated; sensitivity is mandatory | K18: Analyst scenario
A19: VAL_TERMINAL_G | B19: DMX valuation | C19: Terminal growth | D19: % | E19: 0.03 | F19: 0.04 | G19: 0.045 | H19: =INDEX(E19:G19,1,MATCH($C$4,$E$10:$G$10,0)) | I19: Illustrative | J19: Must remain below WACC | K19: Analyst scenario
A20: VAL_ERABLUE | B20: DMX valuation | C20: Fair value of DMX stake in EraBlue | D20: VND bn | E20: 1000 | F20: 1500 | G20: 2000 | H20: =INDEX(E20:G20,1,MATCH($C$4,$E$10:$G$10,0)) | I20: Illustrative | J20: Added once because FCFF EBIT excludes JV earnings | K20: MWG-ERABLUE-JV / analyst scenario
A21: VAL_LEASE | B21: DMX valuation | C21: Lease liabilities in equity bridge | D21: VND bn | E21: 0 | F21: 0 | G21: 0 | H21: =INDEX(E21:G21,1,MATCH($C$4,$E$10:$G$10,0)) | I21: Illustrative placeholder | J21: Replace after verifying the chosen lease convention | K21: Analyst placeholder
A22: VAL_OTHER_CLAIMS | B22: DMX valuation | C22: Other claims in equity bridge | D22: VND bn | E22: 0 | F22: 0 | G22: 0 | H22: =INDEX(E22:G22,1,MATCH($C$4,$E$10:$G$10,0)) | I22: Illustrative placeholder | J22: No unsupported claim is inserted | K22: Analyst placeholder
... A41: SOTP_MWG_SHARES | B41: MWG SOTP | C41: MWG diluted shares | D41: mn shares | E41: 1477.2 | F41: 1477.2 | G41: 1477.2 | H41: =INDEX(E41:G41,1,MATCH($C$4,$E$10:$G$10,0)) | I41: Illustrative placeholder | J41: Replace with verified diluted shares at valuation date | K41: Analyst placeholder

Sheet DMX_Valuation
A1: DMX illustrative FCFF DCF
A2: Management revenue path + explicit analyst EBIT/tax/D&A/capex/NWC drivers. Mid-year convention; explicit pre-IPO Q1 to post-IPO bridge.
B4: FCFF build | C4: 2025A | D4: 2026E | E4: 2027E | F4: 2028E | G4: 2029E | H4: 2030E | J4: Valuation summary | K4: Value | L4: Status | M4: Comment
B5: Data status | C5: Actual / company presentation | D5: Illustrative forecast | E5: Illustrative forecast | F5: Illustrative forecast | G5: Illustrative forecast | H5: Illustrative forecast | J5: Active scenario | K5: =Assumptions!$C$4 | L5: Control | M5: Scenario switch
B6: Management revenue path | C6: =Mgmt_Forecast!C6 | D6: =Mgmt_Forecast!D6 | E6: =Mgmt_Forecast!E6 | F6: =Mgmt_Forecast!F6 | G6: =Mgmt_Forecast!G6 | H6: =Mgmt_Forecast!H6 | J6: WACC | K6: =Assumptions!$H$18 | L6: Illustrative | M6: Nominal VND assumption
B7: Management revenue growth | C7: N/A | D7: =Mgmt_Forecast!D7 | E7: =Mgmt_Forecast!E7 | F7: =Mgmt_Forecast!F7 | G7: =Mgmt_Forecast!G7 | H7: =Mgmt_Forecast!H7 | J7: Terminal growth | K7: =Assumptions!$H$19 | L7: Illustrative | M7: Must be below WACC
B8: Model revenue | C8: =C6 | D8: =C8*(1+D7+D9) | E8: =D8*(1+E7+E9) | F8: =E8*(1+F7+F9) | G8: =F8*(1+G7+G9) | H8: =G8*(1+H7+H9) | J8: Terminal FCFF | K8: =H21*(1+K7) | L8: Calculated | M8: 2030E FCFF grown by g
B9: Scenario growth adjustment | C9: N/A | D9: =Assumptions!$H$11 | E9: =Assumptions!$H$11 | F9: =Assumptions!$H$11 | G9: =Assumptions!$H$11 | H9: =Assumptions!$H$11 | J9: Terminal value | K9: =K8/(K6-K7) | L9: Calculated | M9: Perpetuity growth
B10: Management gross margin reference | C10: =Mgmt_Forecast!C11 | D10: =Mgmt_Forecast!D11 | E10: =Mgmt_Forecast!E11 | F10: =Mgmt_Forecast!F11 | G10: =Mgmt_Forecast!G11 | H10: =Mgmt_Forecast!H11 | J10: PV of terminal value | K10: =K9*H23 | L10: Calculated | M10: Mid-year convention
B11: Management NPAT reference | C11: =Mgmt_Forecast!C8 | D11: =Mgmt_Forecast!D8 | E11: =Mgmt_Forecast!E8 | F11: =Mgmt_Forecast!F8 | G11: =Mgmt_Forecast!G8 | H11: =Mgmt_Forecast!H8 | J11: PV of explicit FCFF | K11: =SUM(D24:H24) | L11: Calculated | M11: 2026E–2030E
B12: Illustrative EBIT margin | C12: N/A | D12: =Assumptions!$H$12 | E12: =D12+Assumptions!$H$13 | F12: =E12+Assumptions!$H$13 | G12: =F12+Assumptions!$H$13 | H12: =G12+Assumptions!$H$13 | J12: Enterprise value | K12: =K10+K11 | L12: Calculated | M12: FCFF enterprise value
B13: EBIT | C13: N/A | D13: =D8*D12 | E13: =E8*E12 | F13: =F8*F12 | G13: =G8*G12 | H13: =H8*H12 | J13: Terminal value / EV | K13: =K10/K12 | L13: Calculated | M13: High percentages require caution
B14: Cash tax rate | C14: N/A | D14: =Assumptions!$H$14 | E14: =Assumptions!$H$14 | F14: =Assumptions!$H$14 | G14: =Assumptions!$H$14 | H14: =Assumptions!$H$14
B15: NOPAT | C15: N/A | D15: =D13*(1-D14) | E15: =E13*(1-E14) | F15: =F13*(1-F14) | G15: =G13*(1-G14) | H15: =H13*(1-H14) | J15: Gross debt | K15: =Q1_Actuals!D36 | L15: Actual at 31-Mar-2026 | M15: Short-term debt; no long-term debt line in source BS
B16: D&A / revenue | C16: N/A | D16: =Assumptions!$H$15 | E16: =Assumptions!$H$15 | F16: =Assumptions!$H$15 | G16: =Assumptions!$H$15 | H16: =Assumptions!$H$15 | J16: Cash & equivalents | K16: =Q1_Actuals!D25 | L16: Actual at 31-Mar-2026 | M16: Pre-IPO balance-sheet cash; later net proceeds are shown separately
B17: D&A | C17: N/A | D17: =D8*D16 | E17: =E8*E16 | F17: =F8*F16 | G17: =G8*G16 | H17: =H8*H16 | J17: Short-term investments | K17: =Q1_Actuals!D26 | L17: Actual at 31-Mar-2026 | M17: Held-to-maturity investments
B18: Capex / revenue | C18: N/A | D18: =Assumptions!$H$16 | E18: =Assumptions!$H$16 | F18: =Assumptions!$H$16 | G18: =Assumptions!$H$16 | H18: =Assumptions!$H$16 | J18: Long-term deposits | K18: =Q1_Actuals!D27 | L18: Actual at 31-Mar-2026 | M18: Held-to-maturity investments
B19: Capex (cash outflow) | C19: N/A | D19: =D8*D18 | E19: =E8*E18 | F19: =F8*F18 | G19: =G8*G18 | H19: =H8*H18 | J19: Lease liabilities | K19: =Assumptions!$H$21 | L19: Illustrative placeholder | M19: Replace when lease convention is verified
B20: Change in NWC (cash outflow) | C20: N/A | D20: =MAX(0,D8-C8)*Assumptions!$H$17 | E20: =MAX(0,E8-D8)*Assumptions!$H$17 | F20: =MAX(0,F8-E8)*Assumptions!$H$17 | G20: =MAX(0,G8-F8)*Assumptions!$H$17 | H20: =MAX(0,H8-G8)*Assumptions!$H$17 | J20: Other claims | K20: =Assumptions!$H$22 | L20: Illustrative placeholder | M20: No unsupported claim inserted
B21: FCFF | C21: N/A | D21: =D15+D17-D19-D20 | E21: =E15+E17-E19-E20 | F21: =F15+F17-F19-F20 | G21: =G15+G17-G19-G20 | H21: =H15+H17-H19-H20 | J21: EraBlue stake value | K21: =Assumptions!$H$20 | L21: Illustrative | M21: Added once; FCFF excludes JV earnings
B22: Discount period | C22: N/A | D22: 0.5 | E22: 1.5 | F22: 2.5 | G22: 3.5 | H22: 4.5 | J22: Net IPO proceeds adjustment | K22: =IPO_Bridge!D20 | L22: Pro forma after 31-Mar-2026 | M22: Estimated net proceeds included once; planned debt repayment is not presented as reported actual
B23: Discount factor | C23: N/A | D23: =1/(1+$K$6)^D22 | E23: =1/(1+$K$6)^E22 | F23: =1/(1+$K$6)^F22 | G23: =1/(1+$K$6)^G22 | H23: =1/(1+$K$6)^H22 | J23: DMX equity value | K23: =K12-K15+K16+K17+K18-K19-K20+K21+K22 | L23: Calculated | M23: EV-to-equity bridge
B24: Present value of FCFF | C24: N/A | D24: =D21*D23 | E24: =E21*E23 | F24: =F21*F23 | G24: =G21*G23 | H24: =H21*H23 | J24: Post-IPO diluted shares | K24: =IPO_Bridge!D11 | L24: Actual | M24: Million shares
J25: DCF value per share | K25: =K23*1000/K24 | L25: Illustrative | M25: VND/share; not a target price
J26: IPO offer price anchor | K26: =IPO_Bridge!D5 | L26: Actual transaction anchor | M26: Not a current market price
B28: Key limitation: an integrated three-statement DMX forecast is not claimed here because the public case set does not contain enough segment disclosures to forecast every balance-sheet line. This transparent FCFF build therefore uses explicit cash-flow drivers and the latest actual cash/debt bridge; assumptions are editable and separately labelled. | J28: Same-date market price / date | K28: ="N/A" | L28: Unavailable | M28: No price/date supplied
J29: Market conclusion | K29: ="UNAVAILABLE — model output only" | L29: Publication guard | M29: No upside/downside or recommendation

Sheet MWG_SOTP
A1: MWG illustrative equity-level SOTP
A2: DMX includes EraBlue once. BHX, An Khang and AVAKids sit outside the DMX perimeter. Parent-only adjustments avoid debt double count.
A4: Asset | B4: Method | C4: Metric | D4: Metric value | E4: Multiple / factor | F4: Net debt / claims | G4: Equity value 100% | H4: MWG ownership | I4: Attributable to MWG | J4: Source / model ref | K4: Double-count bucket | L4: Status / limitation
A5: DMX | B5: FCFF DCF | C5: DMX equity value | D5: =DMX_Valuation!K23 | E5: 1 | F5: 0 | G5: =D5 | H5: =Assumptions!$H$23 | I5: =G5*H5 | J5: DMX_Valuation | K5: DMX_DCF_INCL_ERABLUE | L5: Illustrative; ownership is a rounded proxy
A6: BHX | B6: EV / Sales | C6: Revenue | D6: =Assumptions!$H$24 | E6: =Assumptions!$H$25 | F6: =Assumptions!$H$26 | G6: =D6*E6-F6 | H6: =Assumptions!$H$27 | I6: =G6*H6 | J6: Assumptions | K6: BHX | L6: Illustrative; requires standalone peer/DCF work
A7: An Khang | B7: EV / Sales | C7: Revenue | D7: =Assumptions!$H$28 | E7: =Assumptions!$H$29 | F7: =Assumptions!$H$30 | G7: =D7*E7-F7 | H7: =Assumptions!$H$31 | I7: =G7*H7 | J7: Assumptions | K7: AN_KHANG | L7: Illustrative; outside DMX LFL perimeter
A8: AVAKids | B8: EV / Sales | C8: Revenue | D8: =Assumptions!$H$32 | E8: =Assumptions!$H$33 | F8: =Assumptions!$H$34 | G8: =D8*E8-F8 | H8: =Assumptions!$H$35 | I8: =G8*H8 | J8: Assumptions | K8: AVAKIDS | L8: Illustrative; outside DMX LFL perimeter
A9: Other investments | B9: Equity value | C9: Fixed equity value | D9: =Assumptions!$H$36 | E9: 1 | F9: 0 | G9: =D9*E9-F9 | H9: 1 | I9: =G9*H9 | J9: Assumptions | K9: OTHER_INVESTMENTS | L9: Illustrative placeholder
A10: Parent non-operating assets | B10: Equity value | C10: Fixed equity value | D10: =Assumptions!$H$37 | E10: 1 | F10: 0 | G10: =D10*E10-F10 | H10: 1 | I10: =G10*H10 | J10: Assumptions | K10: PARENT_NONOP_ASSETS | L10: Illustrative placeholder
A13: MWG NAV BRIDGE — ILLUSTRATIVE | G13: Status | H13: Interpretation
A14: Gross attributable asset value | C14: =SUM(I5:I10) | D14: VND bn | G14: Illustrative | H14: Sum of equity values attributable to MWG
A15: Less: parent-only net debt | C15: =Assumptions!$H$38 | D15: VND bn | G15: Illustrative | H15: Not consolidated net debt
A16: Less: parent provisions / claims | C16: =Assumptions!$H$39 | D16: VND bn | G16: Illustrative | H16: Separate parent claims
A17: NAV before holdco discount | C17: =C14-C15-C16 | D17: VND bn | G17: Illustrative | H17: Presented before applying discount
A18: Holding-company discount | C18: =Assumptions!$H$40 | D18: % | G18: Illustrative | H18: Sensitivity, not a target-price plug
A19: NAV after holdco discount | C19: =C17*(1-C18) | D19: VND bn | G19: Illustrative | H19: Illustrative SOTP equity value
A20: MWG diluted shares | C20: =Assumptions!$H$41 | D20: mn shares | G20: Illustrative | H20: Unverified placeholder at this stage
A21: Illustrative SOTP value / share | C21: =C19*1000/C20 | D21: VND/share | G21: Illustrative | H21: Not a target price
A23: Same-date MWG price / date | C23: ="N/A" | D23: N/A | G23: Publication guard | H23: Market data gate not met
A24: Upside/downside or recommendation | C24: ="UNAVAILABLE" | D24: N/A | G24: Publication guard | H24: No market conclusion without verified price/date
A27: Perimeter control — EraBlue appears only within the DMX DCF equity bridge. It is not added as a separate MWG SOTP row. BHX, An Khang and AVAKids are separately valued outside DMX. Parent-only net debt is used because subsidiary values are already equity values; consolidated MWG net debt would double count subsidiary financing.

Sheet Scenarios
A1: Scenario engine & valuation sensitivities
A2: Bear/Base/Bull calculations run independently from the active scenario switch. Outputs are illustrative ranges, not target prices.
A4: Metric | B4: Bear | C4: Base | D4: Bull | E4: Status / interpretation
A5: WACC | B5: =Assumptions!$E$18 | C5: =Assumptions!$F$18 | D5: =Assumptions!$G$18 | E5: Illustrative range — no market recommendation
A6: Terminal growth | B6: =Assumptions!$E$19 | C6: =Assumptions!$F$19 | D6: =Assumptions!$G$19 | E6: Illustrative range — no market recommendation
A7: Revenue growth adjustment | B7: =Assumptions!$E$11 | C7: =Assumptions!$F$11 | D7: =Assumptions!$G$11 | E7: Illustrative range — no market recommendation
A8: 2030E model revenue | B8: =F22 | C8: =L22 | D8: =R22 | E8: Illustrative range — no market recommendation
A9: 2030E EBIT margin | B9: =F23 | C9: =L23 | D9: =R23 | E9: Illustrative range — no market recommendation
A10: 2030E FCFF | B10: =F29 | C10: =L29 | D10: =R29 | E10: Illustrative range — no market recommendation
A11: DMX enterprise value | B11: =F37 | C11: =L37 | D11: =R37 | E11: Illustrative range — no market recommendation
A12: DMX equity value | B12: =F38 | C12: =L38 | D12: =R38 | E12: Illustrative range — no market recommendation
A13: DMX DCF value / share | B13: =F39 | C13: =L39 | D13: =R39 | E13: Illustrative range — no market recommendation
A14: MWG illustrative SOTP / share | B14: =((F38*Assumptions!$E$23)+((Assumptions!$E$24*Assumptions!$E$25-Assumptions!$E$26)*Assumptions!$E$27)+((Assumptions!$E$28*Assumptions!$E$29-Assumptions!$E$30)*Assumptions!$E$31)+((Assumptions!$E$32*Assumptions!$E$33-Assumptions!$E$34)*Assumptions!$E$35)+Assumptions!$E$36+Assumptions!$E$37-Assumptions!$E$38-Assumptions!$E$39)*(1-Assumptions!$E$40)*1000/Assumptions!$E$41 | C14: =((L38*Assumptions!$F$23)+((Assumptions!$F$24*Assumptions!$F$25-Assumptions!$F$26)*Assumptions!$F$27)+((Assumptions!$F$28*Assumptions!$F$29-Assumptions!$F$30)*Assumptions!$F$31)+((Assumptions!$F$32*Assumptions!$F$33-Assumptions!$F$34)*Assumptions!$F$35)+Assumptions!$F$36+Assumptions!$F$37-Assumptions!$F$38-Assumptions!$F$39)*(1-Assumptions!$F$40)*1000/Assumptions!$F$41 | D14: =((R38*Assumptions!$G$23)+((Assumptions!$G$24*Assumptions!$G$25-Assumptions!$G$26)*Assumptions!$G$27)+((Assumptions!$G$28*Assumptions!$G$29-Assumptions!$G$30)*Assumptions!$G$31)+((Assumptions!$G$32*Assumptions!$G$33-Assumptions!$G$34)*Assumptions!$G$35)+Assumptions!$G$36+Assumptions!$G$37-Assumptions!$G$38-Assumptions!$G$39)*(1-Assumptions!$G$40)*1000/Assumptions!$G$41 | E14: Illustrative range — no market recommendation
A15: Holdco discount | B15: =Assumptions!$E$40 | C15: =Assumptions!$F$40 | D15: =Assumptions!$G$40 | E15: Illustrative range — no market recommendation
B20: BEAR — independent FCFF DCF | H20: BASE — independent FCFF DCF | N20: BULL — independent FCFF DCF
B21: 2026E | C21: 2027E | D21: 2028E | E21: 2029E | F21: 2030E | H21: 2026E | I21: 2027E | J21: 2028E | K21: 2029E | L21: 2030E | N21: 2026E | O21: 2027E | P21: 2028E | Q21: 2029E | R21: 2030E
A22: Revenue | B22: =Mgmt_Forecast!C6*(1+Mgmt_Forecast!D7+Assumptions!$E$11) | C22: =B22*(1+Mgmt_Forecast!E7+Assumptions!$E$11) | D22: =C22*(1+Mgmt_Forecast!F7+Assumptions!$E$11) | E22: =D22*(1+Mgmt_Forecast!G7+Assumptions!$E$11) | F22: =E22*(1+Mgmt_Forecast!H7+Assumptions!$E$11) | H22: =Mgmt_Forecast!C6*(1+Mgmt_Forecast!D7+Assumptions!$F$11) | I22: =H22*(1+Mgmt_Forecast!E7+Assumptions!$F$11) | J22: =I22*(1+Mgmt_Forecast!F7+Assumptions!$F$11) | K22: =J22*(1+Mgmt_Forecast!G7+Assumptions!$F$11) | L22: =K22*(1+Mgmt_Forecast!H7+Assumptions!$F$11) | N22: =Mgmt_Forecast!C6*(1+Mgmt_Forecast!D7+Assumptions!$G$11) | O22: =N22*(1+Mgmt_Forecast!E7+Assumptions!$G$11) | P22: =O22*(1+Mgmt_Forecast!F7+Assumptions!$G$11) | Q22: =P22*(1+Mgmt_Forecast!G7+Assumptions!$G$11) | R22: =Q22*(1+Mgmt_Forecast!H7+Assumptions!$G$11)
A23: EBIT margin | B23: =Assumptions!$E$12 | C23: =B23+Assumptions!$E$13 | D23: =C23+Assumptions!$E$13 | E23: =D23+Assumptions!$E$13 | F23: =E23+Assumptions!$E$13 | H23: =Assumptions!$F$12 | I23: =H23+Assumptions!$F$13 | J23: =I23+Assumptions!$F$13 | K23: =J23+Assumptions!$F$13 | L23: =K23+Assumptions!$F$13 | N23: =Assumptions!$G$12 | O23: =N23+Assumptions!$G$13 | P23: =O23+Assumptions!$G$13 | Q23: =P23+Assumptions!$G$13 | R23: =Q23+Assumptions!$G$13
A24: EBIT | B24: =B22*B23 | C24: =C22*C23 | D24: =D22*D23 | E24: =E22*E23 | F24: =F22*F23 | H24: =H22*H23 | I24: =I22*I23 | J24: =J22*J23 | K24: =K22*K23 | L24: =L22*L23 | N24: =N22*N23 | O24: =O22*O23 | P24: =P22*P23 | Q24: =Q22*Q23 | R24: =R22*R23
A25: NOPAT | B25: =B24*(1-Assumptions!$E$14) | C25: =C24*(1-Assumptions!$E$14) | D25: =D24*(1-Assumptions!$E$14) | E25: =E24*(1-Assumptions!$E$14) | F25: =F24*(1-Assumptions!$E$14) | H25: =H24*(1-Assumptions!$F$14) | I25: =I24*(1-Assumptions!$F$14) | J25: =J24*(1-Assumptions!$F$14) | K25: =K24*(1-Assumptions!$F$14) | L25: =L24*(1-Assumptions!$F$14) | N25: =N24*(1-Assumptions!$G$14) | O25: =O24*(1-Assumptions!$G$14) | P25: =P24*(1-Assumptions!$G$14) | Q25: =Q24*(1-Assumptions!$G$14) | R25: =R24*(1-Assumptions!$G$14)
A26: D&A | B26: =B22*Assumptions!$E$15 | C26: =C22*Assumptions!$E$15 | D26: =D22*Assumptions!$E$15 | E26: =E22*Assumptions!$E$15 | F26: =F22*Assumptions!$E$15 | H26: =H22*Assumptions!$F$15 | I26: =I22*Assumptions!$F$15 | J26: =J22*Assumptions!$F$15 | K26: =K22*Assumptions!$F$15 | L26: =L22*Assumptions!$F$15 | N26: =N22*Assumptions!$G$15 | O26: =O22*Assumptions!$G$15 | P26: =P22*Assumptions!$G$15 | Q26: =Q22*Assumptions!$G$15 | R26: =R22*Assumptions!$G$15
A27: Capex | B27: =B22*Assumptions!$E$16 | C27: =C22*Assumptions!$E$16 | D27: =D22*Assumptions!$E$16 | E27: =E22*Assumptions!$E$16 | F27: =F22*Assumptions!$E$16 | H27: =H22*Assumptions!$F$16 | I27: =I22*Assumptions!$F$16 | J27: =J22*Assumptions!$F$16 | K27: =K22*Assumptions!$F$16 | L27: =L22*Assumptions!$F$16 | N27: =N22*Assumptions!$G$16 | O27: =O22*Assumptions!$G$16 | P27: =P22*Assumptions!$G$16 | Q27: =Q22*Assumptions!$G$16 | R27: =R22*Assumptions!$G$16
A28: ΔNWC | B28: =MAX(0,B22-Mgmt_Forecast!C6)*Assumptions!$E$17 | C28: =MAX(0,C22-B22)*Assumptions!$E$17 | D28: =MAX(0,D22-C22)*Assumptions!$E$17 | E28: =MAX(0,E22-D22)*Assumptions!$E$17 | F28: =MAX(0,F22-E22)*Assumptions!$E$17 | H28: =MAX(0,H22-Mgmt_Forecast!C6)*Assumptions!$F$17 | I28: =MAX(0,I22-H22)*Assumptions!$F$17 | J28: =MAX(0,J22-I22)*Assumptions!$F$17 | K28: =MAX(0,K22-J22)*Assumptions!$F$17 | L28: =MAX(0,L22-K22)*Assumptions!$F$17 | N28: =MAX(0,N22-Mgmt_Forecast!C6)*Assumptions!$G$17 | O28: =MAX(0,O22-N22)*Assumptions!$G$17 | P28: =MAX(0,P22-O22)*Assumptions!$G$17 | Q28: =MAX(0,Q22-P22)*Assumptions!$G$17 | R28: =MAX(0,R22-Q22)*Assumptions!$G$17
A29: FCFF | B29: =B25+B26-B27-B28 | C29: =C25+C26-C27-C28 | D29: =D25+D26-D27-D28 | E29: =E25+E26-E27-E28 | F29: =F25+F26-F27-F28 | H29: =H25+H26-H27-H28 | I29: =I25+I26-I27-I28 | J29: =J25+J26-J27-J28 | K29: =K25+K26-K27-K28 | L29: =L25+L26-L27-L28 | N29: =N25+N26-N27-N28 | O29: =O25+O26-O27-O28 | P29: =P25+P26-P27-P28 | Q29: =Q25+Q26-Q27-Q28 | R29: =R25+R26-R27-R28
A30: Discount period | B30: 0.5 | C30: 1.5 | D30: 2.5 | E30: 3.5 | F30: 4.5 | H30: 0.5 | I30: 1.5 | J30: 2.5 | K30: 3.5 | L30: 4.5 | N30: 0.5 | O30: 1.5 | P30: 2.5 | Q30: 3.5 | R30: 4.5
A31: Discount factor | B31: =1/(1+Assumptions!$E$18)^B30 | C31: =1/(1+Assumptions!$E$18)^C30 | D31: =1/(1+Assumptions!$E$18)^D30 | E31: =1/(1+Assumptions!$E$18)^E30 | F31: =1/(1+Assumptions!$E$18)^F30 | H31: =1/(1+Assumptions!$F$18)^H30 | I31: =1/(1+Assumptions!$F$18)^I30 | J31: =1/(1+Assumptions!$F$18)^J30 | K31: =1/(1+Assumptions!$F$18)^K30 | L31: =1/(1+Assumptions!$F$18)^L30 | N31: =1/(1+Assumptions!$G$18)^N30 | O31: =1/(1+Assumptions!$G$18)^O30 | P31: =1/(1+Assumptions!$G$18)^P30 | Q31: =1/(1+Assumptions!$G$18)^Q30 | R31: =1/(1+Assumptions!$G$18)^R30
A32: PV FCFF | B32: =B29*B31 | C32: =C29*C31 | D32: =D29*D31 | E32: =E29*E31 | F32: =F29*F31 | H32: =H29*H31 | I32: =I29*I31 | J32: =J29*J31 | K32: =K29*K31 | L32: =L29*L31 | N32: =N29*N31 | O32: =O29*O31 | P32: =P29*P31 | Q32: =Q29*Q31 | R32: =R29*R31
A34: Terminal value | F34: =F29*(1+Assumptions!$E$19)/(Assumptions!$E$18-Assumptions!$E$19) | L34: =L29*(1+Assumptions!$F$19)/(Assumptions!$F$18-Assumptions!$F$19) | R34: =R29*(1+Assumptions!$G$19)/(Assumptions!$G$18-Assumptions!$G$19)
A35: PV terminal | F35: =F34*F31 | L35: =L34*L31 | R35: =R34*R31
A36: PV explicit | F36: =SUM(B32:F32) | L36: =SUM(H32:L32) | R36: =SUM(N32:R32)
A37: Enterprise value | F37: =F35+F36 | L37: =L35+L36 | R37: =R35+R36
A38: Equity value | F38: =F37-Q1_Actuals!D36+Q1_Actuals!D25+Q1_Actuals!D26+Q1_Actuals!D27-Assumptions!$E$21-Assumptions!$E$22+Assumptions!$E$20 | L38: =L37-Q1_Actuals!D36+Q1_Actuals!D25+Q1_Actuals!D26+Q1_Actuals!D27-Assumptions!$F$21-Assumptions!$F$22+Assumptions!$F$20 | R38: =R37-Q1_Actuals!D36+Q1_Actuals!D25+Q1_Actuals!D26+Q1_Actuals!D27-Assumptions!$G$21-Assumptions!$G$22+Assumptions!$G$20
A39: Value / share | F39: =F38*1000/IPO_Bridge!D11 | L39: =L38*1000/IPO_Bridge!D11 | R39: =R38*1000/IPO_Bridge!D11
A43: DMX DCF VALUE / SHARE — BASE OPERATIONS, WACC × TERMINAL G | J43: MWG SOTP / SHARE — BASE INPUTS, DMX VALUE MULTIPLIER × HOLDCO DISCOUNT
B45: WACC ↓ / g → | C45: 0.02 | D45: 0.03 | E45: 0.04 | F45: 0.05 | G45: 0.06 | J45: DMX value ↓ / discount → | K45: 0 | L45: 0.1 | M45: 0.2 | N45: 0.3
